Workbook

Sheet SMP Scaling
A1: seL4 SMP Benchmark - IPC Throughput Scaling (QEMU TCG, qemu-arm-virt AArch64)
A2: Source: ~/fyp-results/smp_arm_tmr_run1.log (build_smp_tmr, 2026-10-14). Value measured = IPC per second, higher is better. Each pair is core-local (ping and pong both pinned to the same core). RUNS=10, SAMPLE_TIME=100 ms.
A4: Delay (cycles) | B4: Cores | C4: Mean (IPC/s) | D4: Stddev | E4: Stddev % of mean | F4: Ideal linear (IPC/s) | G4: Efficiency vs ideal
A5: 500 | B5: 1 | C5: 176645 | D5: 619.413 | E5: =D5/C5 -> 0.0035065414 | F5: =$C$5*B5 -> 176645 | G5: =C5/F5 -> 1
A6: 500 | B6: 2 | C6: 124811 | D6: 4838.284 | E6: =D6/C6 -> 0.038764885 | F6: =$C$5*B6 -> 353290 | G6: =C6/F6 -> 0.35328201
A7: 500 | B7: 3 | C7: 149818 | D7: 1210.893 | E7: =D7/C7 -> 0.0080824267 | F7: =$C$5*B7 -> 529935 | G7: =C7/F7 -> 0.28271014
A8: 500 | B8: 4 | C8: 145072 | D8: 9044.377 | E8: =D8/C8 -> 0.062344057 | F8: =$C$5*B8 -> 706580 | G8: =C8/F8 -> 0.20531575
A9: 4000 | B9: 1 | C9: 78392 | D9: 546.663 | E9: =D9/C9 -> 0.0069734539 | F9: =$C$9*B9 -> 78392 | G9: =C9/F9 -> 1
A10: 4000 | B10: 2 | C10: 87398 | D10: 10821.999 | E10: =D10/C10 -> 0.12382433 | F10: =$C$9*B10 -> 156784 | G10: =C10/F10 -> 0.55744209
A11: 4000 | B11: 3 | C11: 89829 | D11: 5098.371 | E11: =D11/C11 -> 0.056756404 | F11: =$C$9*B11 -> 235176 | G11: =C11/F11 -> 0.381965
A12: 4000 | B12: 4 | C12: 97945 | D12: 3706.227 | E12: =D12/C12 -> 0.03783988 | F12: =$C$9*B12 -> 313568 | G12: =C12/F12 -> 0.31235649
A13: 32000 | B13: 1 | C13: 14531 | D13: 15.951 | E13: =D13/C13 -> 0.0010977221 | F13: =$C$13*B13 -> 14531 | G13: =C13/F13 -> 1
A14: 32000 | B14: 2 | C14: 25249 | D14: 101.593 | E14: =D14/C14 -> 0.0040236445 | F14: =$C$13*B14 -> 29062 | G14: =C14/F14 -> 0.86879774
A15: 32000 | B15: 3 | C15: 33707 | D15: 437.723 | E15: =D15/C15 -> 0.012986116 | F15: =$C$13*B15 -> 43593 | G15: =C15/F15 -> 0.77322047
A16: 32000 | B16: 4 | C16: 41294 | D16: 804.877 | E16: =D16/C16 -> 0.019491379 | F16: =$C$13*B16 -> 58124 | G16: =C16/F16 -> 0.71044663
A18: Ideal linear = the 1-core mean for that delay multiplied by the core count. Efficiency = measured mean / ideal linear. Perfect scaling would be 100%.

Sheet SMP Scaling (RPi4B)
A1: seL4 SMP Benchmark - IPC Throughput Scaling (Raspberry Pi 4 Model B, 8GB, BCM2711 hardware)
A2: Source: ~/fyp-results/run01..run05 (build_rpi4, 2026-10-14). Value measured = IPC per second, higher is better. Each pair is core-local (ping and pong both pinned to the same core). RUNS=10, SAMPLE_TIME=100 ms. Mean column is the mean of five full power-cycle runs.
A4: Delay (cycles) | B4: Cores | C4: Mean (IPC/s) | D4: Stddev (across runs) | E4: Stddev % of mean | F4: Ideal linear (IPC/s) | G4: Efficiency vs ideal
A5: 500 | B5: 1 | C5: 605711.8 | D5: 78.8 | E5: =D5/C5 -> 0.00013009487 | F5: =$C$5*B5 -> 605711.8 | G5: =C5/F5 -> 1
A6: 500 | B6: 2 | C6: 1094364.4 | D6: 551.4 | E6: =D6/C6 -> 0.00050385411 | F6: =$C$5*B6 -> 1211423.6 | G6: =C6/F6 -> 0.90337055
A7: 500 | B7: 3 | C7: 1401041.8 | D7: 4111.2 | E7: =D7/C7 -> 0.0029343878 | F7: =$C$5*B7 -> 1817135.4 | G7: =C7/F7 -> 0.77101673
A8: 500 | B8: 4 | C8: 1271859.6 | D8: 2048.5 | E8: =D8/C8 -> 0.0016106338 | F8: =$C$5*B8 -> 2422847.2 | G8: =C8/F8 -> 0.52494421
A9: 4000 | B9: 1 | C9: 158258 | D9: 2.7 | E9: =D9/C9 -> 1.7060749e-05 | F9: =$C$9*B9 -> 158258 | G9: =C9/F9 -> 1
A10: 4000 | B10: 2 | C10: 307940.4 | D10: 43.4 | E10: =D10/C10 -> 0.00014093636 | F10: =$C$9*B10 -> 316516 | G10: =C10/F10 -> 0.97290627
A11: 4000 | B11: 3 | C11: 462015.2 | D11: 8.2 | E11: =D11/C11 -> 1.7748334e-05 | F11: =$C$9*B11 -> 474774 | G11: =C11/F11 -> 0.97312658
A12: 4000 | B12: 4 | C12: 614854.4 | D12: 84.3 | E12: =D12/C12 -> 0.00013710563 | F12: =$C$9*B12 -> 633032 | G12: =C12/F12 -> 0.97128486
A13: 32000 | B13: 1 | C13: 22909 | D13: 0 | E13: =D13/C13 -> 0 | F13: =$C$13*B13 -> 22909 | G13: =C13/F13 -> 1
A14: 32000 | B14: 2 | C14: 45635.6 | D14: 0.9 | E14: =D14/C14 -> 1.9721446e-05 | F14: =$C$13*B14 -> 45818 | G14: =C14/F14 -> 0.99601903
A15: 32000 | B15: 3 | C15: 68456 | D15: 0.7 | E15: =D15/C15 -> 1.0225546e-05 | F15: =$C$13*B15 -> 68727 | G15: =C15/F15 -> 0.99605686
A16: 32000 | B16: 4 | C16: 91244.2 | D16: 3.5 | E16: =D16/C16 -> 3.8358603e-05 | F16: =$C$13*B16 -> 91636 | G16: =C16/F16 -> 0.99572439
A18: Ideal linear = the 1-core mean for that delay multiplied by the core count. Efficiency = measured mean / ideal linear. Perfect scaling would be 100%. Note the 500-cycle block: 4 cores delivers lower absolute throughput than 3 cores (1,271,860 against 1,401,042), a regression reproduced in 5 of 5 runs. Stddev here is between the five run means, not within a single run as on the QEMU sheet.

Sheet SMP Scaling (RPi4B pinned)
A1: seL4 SMP Benchmark - IPC Throughput Scaling (Raspberry Pi 4 Model B, 8GB, BCM2711 hardware, ARM clock pinned)
A2: Source: ~/fyp-results/zero0*.log (build_rpi4, 2026-10-21). Value measured = IPC per second, higher is better. Each pair is core-local (ping and pong both pinned to the same core). RUNS=10, SAMPLE_TIME=100 ms. Mean column is the mean of 7 valid full power-cycle runs. force_turbo=1 in config.txt. A delay of 0 cycles means back-to-back IPC.
A4: Delay (cycles) | B4: Cores | C4: Mean (IPC/s) | D4: Stddev (across runs) | E4: Stddev % of mean | F4: Ideal linear (IPC/s) | G4: Efficiency vs ideal
A5: 0 | B5: 1 | C5: 1033039.7 | D5: 1.4 | E5: =D5/C5 -> 1.3552238e-06 | F5: =$C$5*B5 -> 1033039.7 | G5: =C5/F5 -> 1
A6: 0 | B6: 2 | C6: 1423022 | D6: 9127.8 | E6: =D6/C6 -> 0.0064143773 | F6: =$C$5*B6 -> 2066079.4 | G6: =C6/F6 -> 0.68875475
A7: 0 | B7: 3 | C7: 1331568.3 | D7: 895.4 | E7: =D7/C7 -> 0.00067244016 | F7: =$C$5*B7 -> 3099119.1 | G7: =C7/F7 -> 0.42966025
A8: 0 | B8: 4 | C8: 1274272.6 | D8: 665.8 | E8: =D8/C8 -> 0.00052249417 | F8: =$C$5*B8 -> 4132158.8 | G8: =C8/F8 -> 0.30837939
A9: 500 | B9: 1 | C9: 605610.7 | D9: 133.6 | E9: =D9/C9 -> 0.00022060376 | F9: =$C$9*B9 -> 605610.7 | G9: =C9/F9 -> 1
A10: 500 | B10: 2 | C10: 1094838.7 | D10: 323.6 | E10: =D10/C10 -> 0.00029556865 | F10: =$C$9*B10 -> 1211221.4 | G10: =C10/F10 -> 0.90391294
A11: 500 | B11: 3 | C11: 1399994.4 | D11: 3091.2 | E11: =D11/C11 -> 0.0022080088 | F11: =$C$9*B11 -> 1816832.1 | G11: =C11/F11 -> 0.77056895
A12: 500 | B12: 4 | C12: 1270686.9 | D12: 1785 | E12: =D12/C12 -> 0.001404752 | F12: =$C$9*B12 -> 2422442.8 | G12: =C12/F12 -> 0.52454774
A13: 4000 | B13: 1 | C13: 158257.1 | D13: 2.7 | E13: =D13/C13 -> 1.7060846e-05 | F13: =$C$13*B13 -> 158257.1 | G13: =C13/F13 -> 1
A14: 4000 | B14: 2 | C14: 307927.7 | D14: 40.9 | E14: =D14/C14 -> 0.00013282339 | F14: =$C$13*B14 -> 316514.2 | G14: =C14/F14 -> 0.97287168
A15: 4000 | B15: 3 | C15: 461998 | D15: 11.3 | E15: =D15/C15 -> 2.445898e-05 | F15: =$C$13*B15 -> 474771.3 | G15: =C15/F15 -> 0.97309589
A16: 4000 | B16: 4 | C16: 614832.4 | D16: 77.8 | E16: =D16/C16 -> 0.00012653855 | F16: =$C$13*B16 -> 633028.4 | G16: =C16/F16 -> 0.97125563
A17: 32000 | B17: 1 | C17: 22909 | D17: 0 | E17: =D17/C17 -> 0 | F17: =$C$17*B17 -> 22909 | G17: =C17/F17 -> 1
A18: 32000 | B18: 2 | C18: 45634.7 | D18: 0.5 | E18: =D18/C18 -> 1.0956575e-05 | F18: =$C$17*B18 -> 45818 | G18: =C18/F18 -> 0.99599939
A19: 32000 | B19: 3 | C19: 68456.3 | D19: 1.6 | E19: =D19/C19 -> 2.3372575e-05 | F19: =$C$17*B19 -> 68727 | G19: =C19/F19 -> 0.99606123
A20: 32000 | B20: 4 | C20: 91244.9 | D20: 2 | E20: =D20/C20 -> 2.1919033e-05 | F20: =$C$17*B20 -> 91636 | G20: =C20/F20 -> 0.99573203
A22: Ideal linear = the 1-core mean for that delay multiplied by the core count. Efficiency = measured mean / ideal linear. Perfect scaling would be 100%. At 0 cycles throughput peaks at 2 cores (1,423,022) and falls at 3 and 4 cores (1,331,568 and 1,274,273); 3 cores slower than 2 and 4 cores slower than 3 in 7 of 7 runs. At 500 cycles 4 cores is slower than 3 in 7 of 7 runs. 4 cores gives about the same throughput at 0 and 500 cycles (1,274,273 and 1,270,687), consistent with a serialisation ceiling near 1.27M IPC/s. Stddev is between the seven run means, not within a single run as on the QEMU sheet.

Sheet SMP Scaling (RPi4B cross-core)
A1: seL4 SMP Benchmark - IPC Throughput Scaling, Cross-Core Pairs (Raspberry Pi 4 Model B, 8GB, BCM2711 hardware, ARM clock pinned)
A2: Source: ~/fyp-results/cross0*.log (build_rpi4, 2026-10-22). Value measured = IPC per second, higher is better. In each pair the ping thread is pinned to core i and the pong thread to core (i+2) mod 4, so every IPC crosses cores (PONG_CORE_OFFSET 2 in apps/smp/src/main.c). The Cores column counts pairs. RUNS=10, SAMPLE_TIME=100 ms. Mean column is the mean of 6 valid runs. force_turbo=1 in config.txt. A delay of 0 cycles means back-to-back IPC.
A4: Delay (cycles) | B4: Cores | C4: Mean (IPC/s) | D4: Stddev (across runs) | E4: Stddev % of mean | F4: Ideal linear (IPC/s) | G4: Efficiency vs ideal
A5: 0 | B5: 1 | C5: 356843.3 | D5: 245.8 | E5: =D5/C5 -> 0.00068881775 | F5: =$C$5*B5 -> 356843.3 | G5: =C5/F5 -> 1
A6: 0 | B6: 2 | C6: 464257 | D6: 734.9 | E6: =D6/C6 -> 0.0015829594 | F6: =$C$5*B6 -> 713686.6 | G6: =C6/F6 -> 0.65050542
A7: 0 | B7: 3 | C7: 473958.7 | D7: 371.9 | E7: =D7/C7 -> 0.00078466752 | F7: =$C$5*B7 -> 1070529.9 | G7: =C7/F7 -> 0.4427328
A8: 0 | B8: 4 | C8: 491372.8 | D8: 112.1 | E8: =D8/C8 -> 0.00022813636 | F8: =$C$5*B8 -> 1427373.2 | G8: =C8/F8 -> 0.3442497
A9: 500 | B9: 1 | C9: 288020.3 | D9: 973.4 | E9: =D9/C9 -> 0.0033796229 | F9: =$C$9*B9 -> 288020.3 | G9: =C9/F9 -> 1
A10: 500 | B10: 2 | C10: 442512.3 | D10: 816.7 | E10: =D10/C10 -> 0.0018455984 | F10: =$C$9*B10 -> 576040.6 | G10: =C10/F10 -> 0.76819637
A11: 500 | B11: 3 | C11: 483345.3 | D11: 1409 | E11: =D11/C11 -> 0.0029151002 | F11: =$C$9*B11 -> 864060.9 | G11: =C11/F11 -> 0.559388
A12: 500 | B12: 4 | C12: 494807 | D12: 661.1 | E12: =D12/C12 -> 0.0013360765 | F12: =$C$9*B12 -> 1152081.2 | G12: =C12/F12 -> 0.42948969
A13: 4000 | B13: 1 | C13: 122910 | D13: 201.9 | E13: =D13/C13 -> 0.0016426654 | F13: =$C$13*B13 -> 122910 | G13: =C13/F13 -> 1
A14: 4000 | B14: 2 | C14: 232229.7 | D14: 3861.2 | E14: =D14/C14 -> 0.016626642 | F14: =$C$13*B14 -> 245820 | G14: =C14/F14 -> 0.94471443
A15: 4000 | B15: 3 | C15: 328648.7 | D15: 4772.3 | E15: =D15/C15 -> 0.014520976 | F15: =$C$13*B15 -> 368730 | G15: =C15/F15 -> 0.89129905
A16: 4000 | B16: 4 | C16: 410156.8 | D16: 8638.7 | E16: =D16/C16 -> 0.021061945 | F16: =$C$13*B16 -> 491640 | G16: =C16/F16 -> 0.83426247
A17: 32000 | B17: 1 | C17: 21991.5 | D17: 7.1 | E17: =D17/C17 -> 0.00032285201 | F17: =$C$17*B17 -> 21991.5 | G17: =C17/F17 -> 1
A18: 32000 | B18: 2 | C18: 43853.7 | D18: 75.5 | E18: =D18/C18 -> 0.0017216335 | F18: =$C$17*B18 -> 43983 | G18: =C18/F18 -> 0.99706023
A19: 32000 | B19: 3 | C19: 64609 | D19: 308.6 | E19: =D19/C19 -> 0.0047764243 | F19: =$C$17*B19 -> 65974.5 | G19: =C19/F19 -> 0.97930261
A20: 32000 | B20: 4 | C20: 85638.5 | D20: 595.4 | E20: =D20/C20 -> 0.0069524805 | F20: =$C$17*B20 -> 87966 | G20: =C20/F20 -> 0.97354091
A22: Ideal linear = the 1-pair mean for that delay multiplied by the pair count. Efficiency = measured mean / ideal linear. Throughput rose with every added pair at every delay in 6 of 6 runs, so the same-core drop at 3 and 4 cores does not appear here. At 0 cycles the total only rises from 464,257 to 491,373 IPC/s between 2 and 4 pairs (442,512 to 494,807 at 500 cycles). With 2 pairs each core runs one thread; 3 and 4 pairs put two threads on some or all cores, so those rows are not the same workload as the same-core 3 and 4 core rows. Stddev is between the six run means. The 4000-cycle rows vary more across runs (stddev 1.5 to 2.1% of the mean for 2 to 4 pairs) than the same-core campaign (under 0.02%); the cause was not investigated.

Sheet Same vs Cross Core
A1: seL4 SMP Benchmark - Same-Core vs Cross-Core IPC (Raspberry Pi 4 Model B, 8GB, ARM clock pinned)
A2: Same-core = ping and pong on one core (7 runs, sheet 'SMP Scaling (RPi4B pinned)'). Cross-core = ping and pong on different cores (6 runs, sheet 'SMP Scaling (RPi4B cross-core)'). Both use the same kernel build, force_turbo=1, RUNS=10 and SAMPLE_TIME=100 ms. All values are linked to those two sheets. Pairs = number of ping/pong pairs.
A4: Delay (cycles) | B4: Pairs | C4: Same-core mean (IPC/s) | D4: Cross-core mean (IPC/s) | E4: Cross-core as % of same-core | F4: Same-core / cross-core | G4: Same-core efficiency | H4: Cross-core efficiency
A5: ='SMP Scaling (RPi4B pinned)'!A5 -> 0 | B5: ='SMP Scaling (RPi4B pinned)'!B5 -> 1 | C5: ='SMP Scaling (RPi4B pinned)'!C5 -> 1033039.7 | D5: ='SMP Scaling (RPi4B cross-core)'!C5 -> 356843.3 | E5: =D5/C5 -> 0.34543038 | F5: =C5/D5 -> 2.8949393 | G5: ='SMP Scaling (RPi4B pinned)'!G5 -> 1 | H5: ='SMP Scaling (RPi4B cross-core)'!G5 -> 1
A6: ='SMP Scaling (RPi4B pinned)'!A6 -> 0 | B6: ='SMP Scaling (RPi4B pinned)'!B6 -> 2 | C6: ='SMP Scaling (RPi4B pinned)'!C6 -> 1423022 | D6: ='SMP Scaling (RPi4B cross-core)'!C6 -> 464257 | E6: =D6/C6 -> 0.32624724 | F6: =C6/D6 -> 3.06516 | G6: ='SMP Scaling (RPi4B pinned)'!G6 -> 0.68875475 | H6: ='SMP Scaling (RPi4B cross-core)'!G6 -> 0.65050542
A7: ='SMP Scaling (RPi4B pinned)'!A7 -> 0 | B7: ='SMP Scaling (RPi4B pinned)'!B7 -> 3 | C7: ='SMP Scaling (RPi4B pinned)'!C7 -> 1331568.3 | D7: ='SMP Scaling (RPi4B cross-core)'!C7 -> 473958.7 | E7: =D7/C7 -> 0.35594021 | F7: =C7/D7 -> 2.8094606 | G7: ='SMP Scaling (RPi4B pinned)'!G7 -> 0.42966025 | H7: ='SMP Scaling (RPi4B cross-core)'!G7 -> 0.4427328
A8: ='SMP Scaling (RPi4B pinned)'!A8 -> 0 | B8: ='SMP Scaling (RPi4B pinned)'!B8 -> 4 | C8: ='SMP Scaling (RPi4B pinned)'!C8 -> 1274272.6 | D8: ='SMP Scaling (RPi4B cross-core)'!C8 -> 491372.8 | E8: =D8/C8 -> 0.38561043 | F8: =C8/D8 -> 2.5932909 | G8: ='SMP Scaling (RPi4B pinned)'!G8 -> 0.30837939 | H8: ='SMP Scaling (RPi4B cross-core)'!G8 -> 0.3442497
A9: ='SMP Scaling (RPi4B pinned)'!A9 -> 500 | B9: ='SMP Scaling (RPi4B pinned)'!B9 -> 1 | C9: ='SMP Scaling (RPi4B pinned)'!C9 -> 605610.7 | D9: ='SMP Scaling (RPi4B cross-core)'!C9 -> 288020.3 | E9: =D9/C9 -> 0.47558654 | F9: =C9/D9 -> 2.1026667 | G9: ='SMP Scaling (RPi4B pinned)'!G9 -> 1 | H9: ='SMP Scaling (RPi4B cross-core)'!G9 -> 1
A10: ='SMP Scaling (RPi4B pinned)'!A10 -> 500 | B10: ='SMP Scaling (RPi4B pinned)'!B10 -> 2 | C10: ='SMP Scaling (RPi4B pinned)'!C10 -> 1094838.7 | D10: ='SMP Scaling (RPi4B cross-core)'!C10 -> 442512.3 | E10: =D10/C10 -> 0.40418036 | F10: =C10/D10 -> 2.474143 | G10: ='SMP Scaling (RPi4B pinned)'!G10 -> 0.90391294 | H10: ='SMP Scaling (RPi4B cross-core)'!G10 -> 0.76819637
A11: ='SMP Scaling (RPi4B pinned)'!A11 -> 500 | B11: ='SMP Scaling (RPi4B pinned)'!B11 -> 3 | C11: ='SMP Scaling (RPi4B pinned)'!C11 -> 1399994.4 | D11: ='SMP Scaling (RPi4B cross-core)'!C11 -> 483345.3 | E11: =D11/C11 -> 0.34524802 | F11: =C11/D11 -> 2.8964684 | G11: ='SMP Scaling (RPi4B pinned)'!G11 -> 0.77056895 | H11: ='SMP Scaling (RPi4B cross-core)'!G11 -> 0.559388
A12: ='SMP Scaling (RPi4B pinned)'!A12 -> 500 | B12: ='SMP Scaling (RPi4B pinned)'!B12 -> 4 | C12: ='SMP Scaling (RPi4B pinned)'!C12 -> 1270686.9 | D12: ='SMP Scaling (RPi4B cross-core)'!C12 -> 494807 | E12: =D12/C12 -> 0.3894012 | F12: =C12/D12 -> 2.5680455 | G12: ='SMP Scaling (RPi4B pinned)'!G12 -> 0.52454774 | H12: ='SMP Scaling (RPi4B cross-core)'!G12 -> 0.42948969
A13: ='SMP Scaling (RPi4B pinned)'!A13 -> 4000 | B13: ='SMP Scaling (RPi4B pinned)'!B13 -> 1 | C13: ='SMP Scaling (RPi4B pinned)'!C13 -> 158257.1 | D13: ='SMP Scaling (RPi4B cross-core)'!C13 -> 122910 | E13: =D13/C13 -> 0.77664762 | F13: =C13/D13 -> 1.2875852 | G13: ='SMP Scaling (RPi4B pinned)'!G13 -> 1 | H13: ='SMP Scaling (RPi4B cross-core)'!G13 -> 1
A14: ='SMP Scaling (RPi4B pinned)'!A14 -> 4000 | B14: ='SMP Scaling (RPi4B pinned)'!B14 -> 2 | C14: ='SMP Scaling (RPi4B pinned)'!C14 -> 307927.7 | D14: ='SMP Scaling (RPi4B cross-core)'!C14 -> 232229.7 | E14: =D14/C14 -> 0.75416957 | F14: =C14/D14 -> 1.3259618 | G14: ='SMP Scaling (RPi4B pinned)'!G14 -> 0.97287168 | H14: ='SMP Scaling (RPi4B cross-core)'!G14 -> 0.94471443
A15: ='SMP Scaling (RPi4B pinned)'!A15 -> 4000 | B15: ='SMP Scaling (RPi4B pinned)'!B15 -> 3 | C15: ='SMP Scaling (RPi4B pinned)'!C15 -> 461998 | D15: ='SMP Scaling (RPi4B cross-core)'!C15 -> 328648.7 | E15: =D15/C15 -> 0.7113639 | F15: =C15/D15 -> 1.4057503 | G15: ='SMP Scaling (RPi4B pinned)'!G15 -> 0.97309589 | H15: ='SMP Scaling (RPi4B cross-core)'!G15 -> 0.89129905
A16: ='SMP Scaling (RPi4B pinned)'!A16 -> 4000 | B16: ='SMP Scaling (RPi4B pinned)'!B16 -> 4 | C16: ='SMP Scaling (RPi4B pinned)'!C16 -> 614832.4 | D16: ='SMP Scaling (RPi4B cross-core)'!C16 -> 410156.8 | E16: =D16/C16 -> 0.66710343 | F16: =C16/D16 -> 1.4990179 | G16: ='SMP Scaling (RPi4B pinned)'!G16 -> 0.97125563 | H16: ='SMP Scaling (RPi4B cross-core)'!G16 -> 0.83426247
... A20: ='SMP Scaling (RPi4B pinned)'!A20 -> 32000 | B20: ='SMP Scaling (RPi4B pinned)'!B20 -> 4 | C20: ='SMP Scaling (RPi4B pinned)'!C20 -> 91244.9 | D20: ='SMP Scaling (RPi4B cross-core)'!C20 -> 85638.5 | E20: =D20/C20 -> 0.93855657 | F20: =C20/D20 -> 1.0654659 | G20: ='SMP Scaling (RPi4B pinned)'!G20 -> 0.99573203 | H20: ='SMP Scaling (RPi4B cross-core)'!G20 -> 0.97354091
A22: Same-core / cross-core above 1.00x means the same-core pair is faster. The 1-pair rows are the clean per-IPC comparison. The 2-pair cross-core row has one thread per core. The 3 and 4 pair cross-core rows put two threads on some or all cores, so compare them with the same-core rows with that in mind.
A24: Derived cost per ping/pong round trip, 1 pair
A25: Assumed ARM clock (Hz) | C25: 1500000000
A27: Delay (cycles) | B27: Same-core cycles per round trip | C27: Cross-core cycles per round trip | D27: Same-core overhead (cycles) | E27: Cross-core overhead (cycles) | F27: Extra cost of crossing cores (cycles)
A28: 0 | B28: =$C$25/C5 -> 1452.0255 | C28: =$C$25/D5 -> 4203.5257 | D28: =B28-2*A28 -> 1452.0255 | E28: =C28-2*A28 -> 4203.5257 | F28: =E28-D28 -> 2751.5002
A29: 500 | B29: =$C$25/C9 -> 2476.8387 | C29: =$C$25/D9 -> 5207.9662 | D29: =B29-2*A29 -> 1476.8387 | E29: =C29-2*A29 -> 4207.9662 | F29: =E29-D29 -> 2731.1276
A30: 4000 | B30: =$C$25/C13 -> 9478.2477 | C30: =$C$25/D13 -> 12204.052 | D30: =B30-2*A30 -> 1478.2477 | E30: =C30-2*A30 -> 4204.0517 | F30: =E30-D30 -> 2725.804
A31: 32000 | B31: =$C$25/C17 -> 65476.45 | C31: =$C$25/D17 -> 68208.171 | D31: =B31-2*A31 -> 1476.4503 | E31: =C31-2*A31 -> 4208.1713 | F31: =E31-D31 -> 2731.721
A33: Cycles per round trip = clock / mean IPC per second. Overhead = that minus 2 x delay, because both the ping and the pong thread busy-wait for the delay once per round trip. The 1.5 GHz clock is an assumption (nominal Cortex-A72 maximum with force_turbo=1); it is also what makes the same-core 4000 and 32000 cycle overheads agree (about 1,478 cycles). The overhead is roughly constant across delays for each case, about 1,480 same-core and 4,200 cross-core. The 0-cycle same-core figure is about 25 cycles lower than at the other delays; the cause was not determined. This is a derived estimate, not a direct measurement, and it does not identify why crossing cores costs more.

Sheet Notes
A1: Provenance and caveats
A3: Platform | B3: qemu-arm-virt, AArch64, cortex-a53, QEMU TCG emulation (no KVM), -smp 4, 1024 MB
A4: Build directory | B4: ~/sel4bench-arm/build_smp_tmr
A5: Config flags | B5: -DPLATFORM=qemu-arm-virt -DAARCH64=TRUE -DARM_HYP=TRUE -DSMP=TRUE -DIRQUSER=OFF -DSCHED=OFF -DSIGNAL=OFF -DMAPPING=OFF -DSYNC=OFF -DAllowUnstableOverhead=ON -DKernelArmExportPCNTUser=ON -DKernelArmExportPTMRUser=ON
A6: KernelMaxNumNodes | B6: 4
A7: Why ARM_HYP=TRUE | B7: Without it QEMU dumps a DTB with PSCI method = hvc, and the elfloader refuses HVC when MAX_NUM_NODES > 1 (smp-psci.c), so secondary cores never boot. ARM_HYP makes CMake pass virtualization=on, which yields method = smc.
A8: Why AllowUnstableOverhead=ON | B8: The IPC benchmark aborts when its overhead calibration samples are not identical; TCG timing jitter prevents that.
A9: Why SIMULATION was omitted | B9: libplatsupport/CMakeLists.txt sets LibPlatSupportHaveTimer=OFF when (SIMULATION AND KernelArchARM), and the SMP benchmark needs an ltimer. Omitting SIMULATION and exporting PCNT/PTMR satisfies both clauses. Upstream disables this deliberately because TCG timing is not real.
A10: Benchmarks enabled | B10: AppIpcBench, AppSmpBench only (irquser faulted and was disabled)
A11: VALIDITY WARNING | B11: These numbers come from TCG emulation, which time-slices guest cores onto host threads and models neither cache-line behaviour nor real memory latency. They demonstrate that the benchmark harness runs end to end. They are NOT evidence about Big Kernel Lock contention and must not be used as results. The non-monotonic 500-cycle row (1 core slowest, 2 cores fastest) is a symptom of this. Real 1 vs 2 vs 4 core figures must come from hardware (Raspberry Pi).
A12: x86 baseline for comparison | B12: seL4_Call different vspace, 0 words: mean 715 cycles (sd 37) under KVM, 1 core, fastpath on. The AArch64 TCG IPC run showed sd 1376 on a mean of 2533, which is emulation jitter, not kernel behaviour.
A14: Hardware run (Raspberry Pi 4B)
A16: Platform | B16: Raspberry Pi 4 Model B, 8GB, BCM2711, 4x Cortex-A72 r0p3, GIC-400. Passive heatsink, no fan.
A17: Build directory | B17: ~/sel4bench-arm/build_rpi4
A18: Config flags | B18: -DPLATFORM=rpi4 -DAARCH64=TRUE -DSMP=TRUE -DRPI4_MEMORY=8192 -DKernelArmExportPCNTUser=ON -DKernelArmExportPTMRUser=ON -DIRQUSER=OFF -DSCHED=OFF -DSIGNAL=OFF -DMAPPING=OFF -DSYNC=OFF -DElfloaderImage=elf
A19: KernelMaxNumNodes | B19: 4 (CONFIG_MAX_NUM_NODES=4, CONFIG_ENABLE_SMP_SUPPORT=1, both verified in gen_config.h)
A20: Why ARM_HYP was dropped | B20: The RPi4 releases secondary cores through a spin table, not PSCI, so the HVC refusal that forced ARM_HYP on QEMU does not arise. Cores 1-3 confirmed up in every run via the elfloader's 'Core N is up' lines.
A21: Why AllowUnstableOverhead was dropped | B21: Real silicon calibrates consistently. Several IPC microbenchmarks report stddev 0.0 with all 16 samples identical, so the flag is unnecessary and suppressing a genuine calibration failure would contaminate the overhead subtraction.
A22: Boot method | B22: RPi firmware (start4.elf, fixup4.dat, bcm2711-rpi-4-b.dtb) chainloads U-Boot 2024.01. config.txt: arm_64bit=1, enable_uart=1, enable_gic=1, kernel=u-boot.bin, device_tree=bcm2711-rpi-4-b.dtb. U-Boot: fatload mmc 0 0x30000000 <image>; bootelf 0x30000000 (staged high because the ELF links at 0x10000000 and would otherwise overwrite its own headers during the parse).
A23: Benchmarks enabled | B23: AppIpcBench, AppSmpBench only
A24: Repeatability | B24: 5 full power cycles, logged separately via picocom -g. Worst between-run spread anywhere is 0.78%; most rows are under 0.05%. The 129,182 IPC/s gap between 3 and 4 cores at 500 cycles is roughly 63 standard deviations wide.
A25: CLOCK CAVEAT | B25: The ARM clock was not pinned. An earlier manual run measured exactly 2.5x lower on every configuration, consistent with the 600 MHz idle and 1500 MHz boost frequencies. Absolute IPC/s is therefore not comparable across boots. Efficiency is a within-run ratio and is unaffected, so the scaling conclusions stand. Add force_turbo=1 to config.txt before the next campaign.
A26: Open issue | B26: Every run prints 'Range for vaddr 0x10001000 with 1 4k pages not reserved! Mapping new pages to extend brk region failed' before the benchmarks. Both benchmarks complete regardless. Unexplained as of this writing.
A27: Not an error | B27: The repeated 'Failed to allocate object of size N' lines at startup are a halving probe for the largest available untyped object, not a fault.
A28: Result vs QEMU | B28: TCG gave 21% / 31% / 71% efficiency at 4 cores for 500 / 4000 / 32000 cycles. Hardware gives 52% / 97% / 100%. TCG was wrong in magnitude and in shape; its figures are retained on the first sheet only to document that they are unusable.
A30: Hardware run 2 (RPi4B, pinned clock, 0-cycle delay added)
A32: What changed | B32: Same build_rpi4 image type and flags as the first hardware run. Added a fourth row to the delay table in projects/sel4bench/libsel4benchsupport/include/smp.h: { .name = "0 cycles", .delay = 0.00000 } (original saved as smp.h.orig). Rebuilt with ninja only, no reconfigure. Appended force_turbo=1 to config.txt.
A33: Why 0 cycles is valid | B33: The delay is a busy-wait do/while loop on the cycle counter run by both the ping and pong threads (ipc_normal_delay in apps/smp/src/main.c). With a delay of 0 the loop body executes once, so IPCs run back to back. This is the maximum-rate case, not literally zero work per IPC.
A34: Runs | B34: 7 valid full power-cycle runs: zero01, zero02, zero03, zero05, zero06, and two logs both named zero04 (timestamps 210536 and 211730). A third zero04 log (210519) is empty and excluded: picocom was closed during that attempt, so it captured nothing. No failed boots or hangs were reported.
A35: Clock check | B35: With force_turbo=1 the 1-core means match the first hardware campaign: 605,611 against 605,712 at 500 cycles, 158,257 against 158,258 at 4000, 22,909 against 22,909 at 32000. The 4000 and 32000 rows scale at 97% and 99.6% at 4 cores, so there was no thermal throttling despite no fan. The clock caveat on the first hardware run is resolved for this campaign.
A36: 0-cycle result | B36: Efficiency at 4 cores is 30.8% of linear. Total throughput at 4 cores is only 1.23 times a single core and about 10.5% below the 2-core peak. At 3 cores, 0 cycles gives about 4.8% less throughput than 500 cycles, so offering more load lowers throughput.
A37: Interpretation limit | B37: The pattern is consistent with Big Kernel Lock contention but does not isolate the BKL from other shared-state contention. The fastpath locking change is the experiment that does.
A38: Noisiest row | B38: 2 cores at 0 cycles is the noisiest row: stddev 9,128 IPC/s (0.64% of the mean), and a max-minus-min spread of 2.07% of the mean across the 7 runs. The drop from 2 to 3 cores (about 91,454 IPC/s) is still roughly 10 times that stddev.
A39: Open issue (carried over) | B39: The brk-region warning seen at startup in the first campaign has not been investigated, and was not re-checked in these logs.
A41: Hardware run 3 (RPi4B, pinned clock, cross-core pairs)
A43: What changed | B43: Same build_rpi4 configuration as the pinned campaign. In projects/sel4bench/apps/smp/src/main.c added #define PONG_CORE_OFFSET 2 and pinned the pong thread of pair i to core (i + PONG_CORE_OFFSET) % nr_cores (original saved as main.c.orig). Setting the offset to 0 restores same-core pairs. Rebuilt with ninja only. Both images are kept in ~/fyp-results/images.
A44: Thread layout | B44: 1 pair uses cores 0 and 2. 2 pairs use all four cores with one thread each. 3 pairs put two threads on cores 0 and 2; 4 pairs put two threads on every core. The Cores column counts pairs, so the 3 and 4 pair rows are a different workload from the same-core rows.
A45: Runs | B45: 6 valid runs: cross01_082313, cross02_082403, cross02_083322, cross03_082454, cross04_082554 and cross05_082649. Each is taken as a separate power cycle. Two cross01 logs (082225 and 082249) are 0 bytes, with no serial output at all, and are excluded. No hangs or failed boots were reported.
A46: 1-pair result | B46: One cross-core pair is slower than one same-core pair by 2.90x at 0 cycles, 2.10x at 500, 1.29x at 4000 and 1.04x at 32000. The gap is a roughly constant cost per round trip (about 2,700 extra cycles on an assumed 1.5 GHz clock), so it matters most when the delay is short.
A47: Scaling result | B47: Cross-core throughput rose with every added pair at every delay in 6 of 6 runs. At 0 and 500 cycles it stays between 0.47M and 0.49M IPC/s from 3 pairs, about 2.6x below the same-core 4-core figures (1.27M). At 4000 and 32000 cycles cross-core efficiency at 4 pairs is 83.4% and 97.4%, against 97.1% and 99.6% same-core.
...
